Workbook

Sheet Voti
C1: Nome | D1: Nome | E1: Cognome | F1: Numero di matricola | G1: D1 (6) | H1: D2 (5) | I1: D3 (5) | J1: D4 (5) | K1: D5 (6) | L1: D6 (3) | M1: TOT. | N1: TOT. ARR.
C2: ASIA FATIMA PARADISO | D2: Paradiso | E2: Asia Fatima | F2: N86005472 | G2: 5.5 | H2: 5 | I2: 4 | J2: 3.5 | K2: 6 | L2: 2.5 | M2: =SUM(G2:L2) -> 26.5 | N2: =IF($M2=0,"N/A",IF(_xlfn.CEILING.MATH($M2)<18,"INSUFF.",_xlfn.CEILING.MATH($M2))) -> 27
C3: ALESSANDRA PISA | D3: Pisa | E3: Alessandra | F3: N86005479 | G3: 6 | H3: 5 | I3: 5 | J3: 5 | K3: 6 | L3: 2 | M3: =SUM(G3:L3) -> 29 | N3: =IF($M3=0,"N/A",IF(_xlfn.CEILING.MATH($M3)<18,"INSUFF.",_xlfn.CEILING.MATH($M3))) -> 29
C4: ALESSANDRO SALZANO | D4: Salzano | E4: Alessandro | F4: N86005732 | G4: 5.5 | H4: 5 | I4: 4.5 | J4: 5 | K4: 2 | M4: =SUM(G4:L4) -> 22 | N4: =IF($M4=0,"N/A",IF(_xlfn.CEILING.MATH($M4)<18,"INSUFF.",_xlfn.CEILING.MATH($M4))) -> 22
C5: ALESSANDRO SORRENTINO | D5: Sorrentino | E5: Alessandro | F5: N86005583 | G5: 4 | K5: 2 | L5: 2 | M5: =SUM(G5:L5) -> 8 | N5: =IF($M5=0,"N/A",IF(_xlfn.CEILING.MATH($M5)<18,"INSUFF.",_xlfn.CEILING.MATH($M5))) -> INSUFF.
C6: ALFREDO SPINOSA | D6: Spinosa | E6: Alfredo | F6: N86005488 | M6: =SUM(G6:L6) -> 0 | N6: =IF($M6=0,"N/A",IF(_xlfn.CEILING.MATH($M6)<18,"INSUFF.",_xlfn.CEILING.MATH($M6))) -> N/A
C7: ANDREA PIROZZI | D7: Pirozzi | E7: Andrea | F7: N86005460 | G7: 4 | I7: 5 | J7: 4 | K7: 6 | M7: =SUM(G7:L7) -> 19 | N7: =IF($M7=0,"N/A",IF(_xlfn.CEILING.MATH($M7)<18,"INSUFF.",_xlfn.CEILING.MATH($M7))) -> 19
C8: ARTEM PRYKHODKO | D8: Prykhodko | E8: Artem | F8: N86005753 | G8: 2 | I8: 2.5 | J8: 5 | K8: 6 | L8: 3 | M8: =SUM(G8:L8) -> 18.5 | N8: =IF($M8=0,"N/A",IF(_xlfn.CEILING.MATH($M8)<18,"INSUFF.",_xlfn.CEILING.MATH($M8))) -> 19
C9: CHRISTIAN PETRUCCI | D9: Petrucci | E9: Christian | F9: N86005552 | G9: 5 | H9: 5 | I9: 5 | J9: 5 | K9: 6 | M9: =SUM(G9:L9) -> 26 | N9: =IF($M9=0,"N/A",IF(_xlfn.CEILING.MATH($M9)<18,"INSUFF.",_xlfn.CEILING.MATH($M9))) -> 26
C10: CHRISTIAN PICCIRILLO | D10: Piccirillo | E10: Christian | F10: N86005503 | G10: 5.5 | H10: 5 | I10: 5 | J10: 4 | K10: 6 | M10: =SUM(G10:L10) -> 25.5 | N10: =IF($M10=0,"N/A",IF(_xlfn.CEILING.MATH($M10)<18,"INSUFF.",_xlfn.CEILING.MATH($M10))) -> 26
C11: CIRO ZOTTOLO | D11: Zottolo | E11: Ciro | F11: N86005745 | G11: 4.5 | H11: 4 | I11: 3.5 | J11: 4.5 | K11: 4 | L11: 2 | M11: =SUM(G11:L11) -> 22.5 | N11: =IF($M11=0,"N/A",IF(_xlfn.CEILING.MATH($M11)<18,"INSUFF.",_xlfn.CEILING.MATH($M11))) -> 23
C12: CLAUDIO JUNIOR NARRETTI | D12: Narretti | E12: Claudio Junior | F12: N86005495 | G12: 5 | H12: 5 | I12: 5 | J12: 5 | M12: =SUM(G12:L12) -> 20 | N12: =IF($M12=0,"N/A",IF(_xlfn.CEILING.MATH($M12)<18,"INSUFF.",_xlfn.CEILING.MATH($M12))) -> 20
C13: DANIELE SIBILLA | D13: Sibilla | E13: Daniele | F13: N86005427 | G13: 5.5 | H13: 4.5 | I13: 2 | J13: 4 | K13: 6 | L13: 3 | M13: =SUM(G13:L13) -> 25 | N13: =IF($M13=0,"N/A",IF(_xlfn.CEILING.MATH($M13)<18,"INSUFF.",_xlfn.CEILING.MATH($M13))) -> 25
C14: DAVIDE ALEXANDER PUCA | D14: Puca | E14: Davide | F14: N86005725 | G14: 5 | H14: 5 | I14: 3.5 | J14: 3 | K14: 6 | M14: =SUM(G14:L14) -> 22.5 | N14: =IF($M14=0,"N/A",IF(_xlfn.CEILING.MATH($M14)<18,"INSUFF.",_xlfn.CEILING.MATH($M14))) -> 23
C15: DMYTRO PYLYPIV | D15: Pylypiv | E15: Dmytro | F15: N86005664 | G15: 1.5 | H15: 4.5 | I15: 4 | J15: 3.5 | K15: 6 | M15: =SUM(G15:L15) -> 19.5 | N15: =IF($M15=0,"N/A",IF(_xlfn.CEILING.MATH($M15)<18,"INSUFF.",_xlfn.CEILING.MATH($M15))) -> 20
C16: EMILIO PINTO | D16: Pinto | E16: Emilio | F16: N86005469 | G16: 5.5 | H16: 5 | I16: 3 | J16: 3 | K16: 5.5 | L16: 2 | M16: =SUM(G16:L16) -> 24 | N16: =IF($M16=0,"N/A",IF(_xlfn.CEILING.MATH($M16)<18,"INSUFF.",_xlfn.CEILING.MATH($M16))) -> 24
C17: EMMANUELE PREZIOSO | D17: Prezioso | E17: Emmanuele | F17: N86005530 | G17: 4 | H17: 4.5 | I17: 5 | J17: 5 | K17: 6 | L17: 3 | M17: =SUM(G17:L17) -> 27.5 | N17: =IF($M17=0,"N/A",IF(_xlfn.CEILING.MATH($M17)<18,"INSUFF.",_xlfn.CEILING.MATH($M17))) -> 28
C18: FABIO ROSIELLO | D18: Rosiello | E18: Fabio | F18: N86005482 | G18: 6 | H18: 5 | I18: 4 | J18: 3.5 | L18: 6 | M18: =SUM(G18:L18) -> 24.5 | N18: =IF($M18=0,"N/A",IF(_xlfn.CEILING.MATH($M18)<18,"INSUFF.",_xlfn.CEILING.MATH($M18))) -> 25
C19: FABIO PALMIERI | D19: Palmieri | E19: Fabio | F19: N86005665 | G19: 4 | H19: 4.5 | I19: 4 | J19: 2.5 | K19: 4 | L19: 3 | M19: =SUM(G19:L19) -> 22 | N19: =IF($M19=0,"N/A",IF(_xlfn.CEILING.MATH($M19)<18,"INSUFF.",_xlfn.CEILING.MATH($M19))) -> 22
C20: FILIPPO SACCO | D20: Sacco | E20: Filippo | F20: N86005527 | G20: 4.5 | H20: 5 | I20: 4 | J20: 5 | K20: 5.5 | L20: 1 | M20: =SUM(G20:L20) -> 25 | N20: =IF($M20=0,"N/A",IF(_xlfn.CEILING.MATH($M20)<18,"INSUFF.",_xlfn.CEILING.MATH($M20))) -> 25
C21: FRANCESCO RAIMO | D21: Raimo | E21: Francesco | F21: N86005736 | G21: 6 | H21: 5 | I21: 5 | J21: 5 | K21: 6 | L21: 3 | M21: =SUM(G21:L21) -> 30 | N21: =IF($M21=0,"N/A",IF(_xlfn.CEILING.MATH($M21)<18,"INSUFF.",_xlfn.CEILING.MATH($M21))) -> 30
C22: FRANCESCO RONCA | D22: Ronca | E22: Francesco | F22: N86005712 | G22: 4.5 | I22: 4.5 | J22: 4 | K22: 6 | L22: 2.5 | M22: =SUM(G22:L22) -> 21.5 | N22: =IF($M22=0,"N/A",IF(_xlfn.CEILING.MATH($M22)<18,"INSUFF.",_xlfn.CEILING.MATH($M22))) -> 22
C23: FRANCESCO PIO PARAGLIOLA | D23: Paragliola | E23: Francesco Pio | F23: N86005491 | G23: 6 | H23: 5 | I23: 5 | K23: 5 | M23: =SUM(G23:L23) -> 21 | N23: =IF($M23=0,"N/A",IF(_xlfn.CEILING.MATH($M23)<18,"INSUFF.",_xlfn.CEILING.MATH($M23))) -> 21
C24: FRANCESCO PIO PERROTTA | D24: Francesco Pio | E24: Perrotta | F24: N86005816 | G24: 5.5 | H24: 4.5 | I24: 2 | J24: 2 | K24: 2.5 | L24: 1 | M24: =SUM(G24:L24) -> 17.5 | N24: =IF($M24=0,"N/A",IF(_xlfn.CEILING.MATH($M24)<18,"INSUFF.",_xlfn.CEILING.MATH($M24))) -> 18
C25: FRANCO ANIELLO ORICCHIO | D25: Oricchio | E25: Franco Aniello | F25: N86005632 | G25: 1 | H25: 0 | J25: 5 | L25: 3 | M25: =SUM(G25:L25) -> 9 | N25: =IF($M25=0,"N/A",IF(_xlfn.CEILING.MATH($M25)<18,"INSUFF.",_xlfn.CEILING.MATH($M25))) -> INSUFF.
C26: GIOVANNI PETRELLA | D26: Petrella | E26: Giovanni | F26: N86005547 | G26: 6 | H26: 5 | I26: 4.5 | J26: 4 | K26: 6 | M26: =SUM(G26:L26) -> 25.5 | N26: =IF($M26=0,"N/A",IF(_xlfn.CEILING.MATH($M26)<18,"INSUFF.",_xlfn.CEILING.MATH($M26))) -> 26
C27: GIUSEPPE PAESANO | D27: Paesano | E27: Giuseppe | F27: N86005558 | G27: 6 | H27: 5 | I27: 3.5 | J27: 3.5 | K27: 6 | M27: =SUM(G27:L27) -> 24 | N27: =IF($M27=0,"N/A",IF(_xlfn.CEILING.MATH($M27)<18,"INSUFF.",_xlfn.CEILING.MATH($M27))) -> 24
C28: GIUSEPPE RICCARDI | D28: Riccardi | E28: Giuseppe | F28: N86005587 | G28: 4 | H28: 5 | I28: 4.5 | J28: 2 | L28: 1 | M28: =SUM(G28:L28) -> 16.5 | N28: =IF($M28=0,"N/A",IF(_xlfn.CEILING.MATH($M28)<18,"INSUFF.",_xlfn.CEILING.MATH($M28))) -> INSUFF.
C29: GIUSEPPE RUSSO | D29: Russo | E29: Giuseppe | F29: N86005813 | G29: 4.5 | H29: 2.5 | I29: 3.5 | J29: 2.5 | K29: 6 | L29: 2.5 | M29: =SUM(G29:L29) -> 21.5 | N29: =IF($M29=0,"N/A",IF(_xlfn.CEILING.MATH($M29)<18,"INSUFF.",_xlfn.CEILING.MATH($M29))) -> 22
C30: GIUSEPPE STRIANO | D30: Striano | E30: Giuseppe | F30: N86005849 | G30: 4 | H30: 5 | I30: 2.5 | J30: 3 | K30: 6 | L30: 3 | M30: =SUM(G30:L30) -> 23.5 | N30: =IF($M30=0,"N/A",IF(_xlfn.CEILING.MATH($M30)<18,"INSUFF.",_xlfn.CEILING.MATH($M30))) -> 24
C31: KRISTIAN SAPONARO | D31: Saponaro | E31: Kristian | F31: N86005723 | G31: 5.5 | H31: 1 | I31: 4.5 | J31: 3.5 | K31: 6 | L31: 1 | M31: =SUM(G31:L31) -> 21.5 | N31: =IF($M31=0,"N/A",IF(_xlfn.CEILING.MATH($M31)<18,"INSUFF.",_xlfn.CEILING.MATH($M31))) -> 22
C32: LARA RUSSO | D32: Russo | E32: Lara | F32: N86005540 | G32: 4.5 | H32: 5 | I32: 4.5 | J32: 3 | M32: =SUM(G32:L32) -> 17 | N32: =IF($M32=0,"N/A",IF(_xlfn.CEILING.MATH($M32)<18,"INSUFF.",_xlfn.CEILING.MATH($M32))) -> INSUFF.
C33: LENNY RUSCIANO | D33: Rusciano | E33: Lenny | F33: N86005704 | I33: 5 | J33: 4 | K33: 5.5 | L33: 3 | M33: =SUM(G33:L33) -> 17.5 | N33: =IF($M33=0,"N/A",IF(_xlfn.CEILING.MATH($M33)<18,"INSUFF.",_xlfn.CEILING.MATH($M33))) -> 18
C34: LIBERATO SANNINO | D34: Sannino | E34: Liberato | F34: N86005724 | M34: =SUM(G34:L34) -> 0 | N34: =IF($M34=0,"N/A",IF(_xlfn.CEILING.MATH($M34)<18,"INSUFF.",_xlfn.CEILING.MATH($M34))) -> N/A
C35: LORENZO ROSSI | D35: Rossi | E35: Lorenzo | F35: N86005673 | G35: 5 | H35: 5 | I35: 5 | J35: 4.5 | K35: 6 | L35: 2.5 | M35: =SUM(G35:L35) -> 28 | N35: =IF($M35=0,"N/A",IF(_xlfn.CEILING.MATH($M35)<18,"INSUFF.",_xlfn.CEILING.MATH($M35))) -> 28
C36: LUCA PATRUNO | D36: Patruno | E36: Luca | F36: N86005513 | M36: =SUM(G36:L36) -> 0 | N36: =IF($M36=0,"N/A",IF(_xlfn.CEILING.MATH($M36)<18,"INSUFF.",_xlfn.CEILING.MATH($M36))) -> N/A
C37: LUIGI RAIOLA | D37: raiola | E37: luigi | F37: N86005694 | M37: =SUM(G37:L37) -> 0 | N37: =IF($M37=0,"N/A",IF(_xlfn.CEILING.MATH($M37)<18,"INSUFF.",_xlfn.CEILING.MATH($M37))) -> N/A
C38: MATTIA PERNA | D38: PERNA | E38: MATTIA | F38: N86005414 | G38: 5 | H38: 5 | I38: 3.5 | J38: 2.5 | K38: 6 | M38: =SUM(G38:L38) -> 22 | N38: =IF($M38=0,"N/A",IF(_xlfn.CEILING.MATH($M38)<18,"INSUFF.",_xlfn.CEILING.MATH($M38))) -> 22
C39: MATTIA STAVOLO | D39: Stavolo | E39: Mattia | F39: N86005456 | G39: 2 | H39: 5 | I39: 4 | J39: 6 | K39: 3.5 | L39: 2.5 | M39: =SUM(G39:L39) -> 23 | N39: =IF($M39=0,"N/A",IF(_xlfn.CEILING.MATH($M39)<18,"INSUFF.",_xlfn.CEILING.MATH($M39))) -> 23
C40: NUNZIA PALUMBO | D40: palumbo | E40: nunzia | F40: N86005758 | G40: 6 | H40: 5 | I40: 5 | J40: 5 | K40: 6 | L40: 3 | M40: =SUM(G40:L40) -> 30 | N40: =IF($M40=0,"N/A",IF(_xlfn.CEILING.MATH($M40)<18,"INSUFF.",_xlfn.CEILING.MATH($M40))) -> 30
...

Sheet Pub
A1: Numero di matricola | B1: Voto
A2: N86005414 | B2: =Voti!$N38 -> 22
A3: N86005416 | B3: =Voti!$N45 -> 23
A4: N86005419 | B4: =Voti!$N46 -> 27
A5: N86005425 | B5: =Voti!$N49 -> 29
A6: N86005427 | B6: =Voti!$N13 -> 25
A7: N86005441 | B7: =Voti!$N51 -> 26
A8: N86005456 | B8: =Voti!$N39 -> 23
A9: N86005460 | B9: =Voti!$N7 -> 19
A10: N86005469 | B10: =Voti!$N16 -> 24
A11: N86005472 | B11: =Voti!$N2 -> 27
A12: N86005479 | B12: =Voti!$N3 -> 29
A13: N86005482 | B13: =Voti!$N18 -> 25
A14: N86005484 | B14: =Voti!$N53 -> INSUFF.
A15: N86005488 | B15: =Voti!$N6 -> N/A
A16: N86005491 | B16: =Voti!$N23 -> 21
A17: N86005495 | B17: =Voti!$N12 -> 20
A18: N86005500 | B18: =Voti!$N52 -> 25
A19: N86005503 | B19: =Voti!$N10 -> 26
A20: N86005513 | B20: =Voti!$N36 -> N/A
A21: N86005527 | B21: =Voti!$N20 -> 25
A22: N86005530 | B22: =Voti!$N17 -> 28
A23: N86005540 | B23: =Voti!$N32 -> INSUFF.
A24: N86005547 | B24: =Voti!$N26 -> 26
A25: N86005552 | B25: =Voti!$N9 -> 26
A26: N86005558 | B26: =Voti!$N27 -> 24
A27: N86005571 | B27: =Voti!$N43 -> 25
A28: N86005576 | B28: =Voti!$N47 -> 25
A29: N86005583 | B29: =Voti!$N5 -> INSUFF.
A30: N86005587 | B30: =Voti!$N28 -> INSUFF.
A31: N86005596 | B31: =Voti!$N48 -> 18
A32: N86005627 | B32: =Voti!$N54 -> INSUFF.
A33: N86005632 | B33: =Voti!$N25 -> INSUFF.
A34: N86005646 | B34: =Voti!$N41 -> 28
A35: N86005664 | B35: =Voti!$N15 -> 20
A36: N86005665 | B36: =Voti!$N19 -> 22
A37: N86005673 | B37: =Voti!$N35 -> 28
A38: N86005682 | B38: =Voti!$N44 -> 30
A39: N86005694 | B39: =Voti!$N37 -> N/A
A40: N86005704 | B40: =Voti!$N33 -> 18
...
